Workbook
Name IQ_CH: 110000
Name IQ_CQ: 5000
Name IQ_CY: 10000
Name IQ_DAILY: 500000
Name IQ_FH: 100000
Name IQ_FQ: 500
Name IQ_FY: 1000
Name IQ_LTM: 2000
Name IQ_MONTH: 15000
Name IQ_NTM: 6000
Name IQ_WEEK: 50000
Name IQ_YTD: 3000

Sheet Tall Firs
B1: Capitalization | C1: Name | D1: Ticker | E1: Shares | F1: Price | G1: Market Value | H1: Last Update Price | I1: Last Update Date | J1: Passive Weight | K1: Class Weight | L1: Portfolio Weight | M1: Active Weight | N1: Last Update ETF Price | O1: Market Return Since Update | P1: Return Since Update | Q1: Excess Return Since Update | R1: Update Status | S1: Days Since Update
A2: TMT | B2: =IFERROR(__xludf.DUMMYFUNCTION("IF(GOOGLEFINANCE(D2,""marketcap"")/1000000>10000,""Large Cap"",IF(GOOGLEFINANCE(D2,""marketcap"")/1000000>2000,""Mid Cap"",""Small Cap""))"),"Large Cap") -> Large Cap | C2: =IFERROR(__xludf.DUMMYFUNCTION("GOOGLEFINANCE(D2,""Name"")"),"Apple Inc") -> Apple Inc | D2: AAPL | E2: 328.4268 | F2: =IFERROR(__xludf.DUMMYFUNCTION("GOOGLEFINANCE(D2,""price"")"),283.78) -> 283.78 | G2: =F2*E2 -> 93200.957 | H2: 170 | I2: 44588 | J2: 0.0604 | K2: =G2/($G$37-$G$36-$G$35) -> 0.045386255 | L2: =G2/($G$37-$G$35) -> 0.034446032 | M2: =L2-J2 -> -0.025953968 | N2: 249.65 | O2: =$F$36/N2-1 -> 0.67133988 | P2: =F2/H2-1 -> 0.66929412 | Q2: =P2-O2 -> -0.0020457582 | R2: Winter 24 | S2: =TODAY()-I2 -> 1611
A3: TMT | B3: =IFERROR(__xludf.DUMMYFUNCTION("IF(GOOGLEFINANCE(D3,""marketcap"")/1000000>10000,""Large Cap"",IF(GOOGLEFINANCE(D3,""marketcap"")/1000000>2000,""Mid Cap"",""Small Cap""))"),"Mid Cap") -> Mid Cap | C3: =IFERROR(__xludf.DUMMYFUNCTION("GOOGLEFINANCE(D3,""Name"")"),"ACI Worldwide Inc") -> ACI Worldwide Inc | D3: ACIW | E3: 1103 | F3: =IFERROR(__xludf.DUMMYFUNCTION("GOOGLEFINANCE(D3,""price"")"),49.26) -> 49.26 | G3: =F3*E3 -> 54333.78 | H3: 36.09 | I3: 45415 | J3: 0.0001 | K3: =G3/($G$37-$G$36-$G$35) -> 0.026459029 | L3: =G3/($G$37-$G$35) -> 0.020081158 | M3: =L3-J3 -> 0.019981158 | N3: 295.77 | O3: =$F$36/N3-1 -> 0.41072455 | P3: =F3/H3-1 -> 0.36492103 | Q3: =P3-O3 -> -0.045803519 | S3: =TODAY()-I3 -> 784
A4: Consumer | B4: =IFERROR(__xludf.DUMMYFUNCTION("IF(GOOGLEFINANCE(D4,""marketcap"")/1000000>10000,""Large Cap"",IF(GOOGLEFINANCE(D4,""marketcap"")/1000000>2000,""Mid Cap"",""Small Cap""))"),"Large Cap") -> Large Cap | C4: =IFERROR(__xludf.DUMMYFUNCTION("GOOGLEFINANCE(D4,""Name"")"),"Amazon.com Inc") -> Amazon.com Inc | D4: AMZN | E4: 360 | F4: =IFERROR(__xludf.DUMMYFUNCTION("GOOGLEFINANCE(D4,""price"")"),232.69) -> 232.69 | G4: =F4*E4 -> 83768.4 | H4: 98.49 | I4: 44877 | J4: 0.0312 | K4: =G4/($G$37-$G$36-$G$35) -> 0.040792864 | L4: =G4/($G$37-$G$35) -> 0.030959864 | M4: =L4-J4 -> -0.00024013579 | N4: 231.01 | O4: =$F$36/N4-1 -> 0.80619887 | P4: =F4/H4-1 -> 1.3625749 | Q4: =P4-O4 -> 0.55637601 | S4: =TODAY()-I4 -> 1322
A5: TMT | B5: =IFERROR(__xludf.DUMMYFUNCTION("IF(GOOGLEFINANCE(D5,""marketcap"")/1000000>10000,""Large Cap"",IF(GOOGLEFINANCE(D5,""marketcap"")/1000000>2000,""Mid Cap"",""Small Cap""))"),"Large Cap") -> Large Cap | C5: =IFERROR(__xludf.DUMMYFUNCTION("GOOGLEFINANCE(D5,""Name"")"),"Broadcom Inc") -> Broadcom Inc | D5: AVGO | E5: 435.8878 | F5: =IFERROR(__xludf.DUMMYFUNCTION("GOOGLEFINANCE(D5,""price"")"),365.02) -> 365.02 | G5: =F5*E5 -> 159107.76 | H5: 120 | I5: 45310 | J5: 0.0139 | K5: =G5/($G$37-$G$36-$G$35) -> 0.077481024 | L5: =G5/($G$37-$G$35) -> 0.058804451 | M5: =L5-J5 -> 0.044904451 | N5: 275 | O5: =$F$36/N5-1 -> 0.51727273 | P5: =F5/H5-1 -> 2.0418333 | Q5: =P5-O5 -> 1.5245606 | S5: =TODAY()-I5 -> 889
A6: Consumer | B6: =IFERROR(__xludf.DUMMYFUNCTION("IF(GOOGLEFINANCE(D6,""marketcap"")/1000000>10000,""Large Cap"",IF(GOOGLEFINANCE(D6,""marketcap"")/1000000>2000,""Mid Cap"",""Small Cap""))"),"Large Cap") -> Large Cap | C6: =IFERROR(__xludf.DUMMYFUNCTION("GOOGLEFINANCE(D6,""Name"")"),"Bunge Global SA") -> Bunge Global SA | D6: BG | E6: 388.1544 | F6: =IFERROR(__xludf.DUMMYFUNCTION("GOOGLEFINANCE(D6,""price"")"),110.54) -> 110.54 | G6: =F6*E6 -> 42906.587 | H6: 105.87 | I6: 44621 | J6: 0.0002 | K6: =G6/($G$37-$G$36-$G$35) -> 0.020894306 | L6: =G6/($G$37-$G$35) -> 0.015857795 | M6: =L6-J6 -> 0.015657795 | N6: 250.62 | O6: =$F$36/N6-1 -> 0.66487112 | P6: =F6/H6-1 -> 0.044110702 | Q6: =P6-O6 -> -0.62076042 | R6: Winter 24 | S6: =TODAY()-I6 -> 1578
A7: TMT | B7: =IFERROR(__xludf.DUMMYFUNCTION("IF(GOOGLEFINANCE(D7,""marketcap"")/1000000>10000,""Large Cap"",IF(GOOGLEFINANCE(D7,""marketcap"")/1000000>2000,""Mid Cap"",""Small Cap""))"),"Mid Cap") -> Mid Cap | C7: =IFERROR(__xludf.DUMMYFUNCTION("GOOGLEFINANCE(D7,""Name"")"),"BILL Holdings Inc") -> BILL Holdings Inc | D7: BILL | E7: 650 | F7: =IFERROR(__xludf.DUMMYFUNCTION("GOOGLEFINANCE(D7,""price"")"),35.52) -> 35.52 | G7: =F7*E7 -> 23088 | H7: 49.38 | I7: 45720 | J7: 0.0001 | K7: =G7/($G$37-$G$36-$G$35) -> 0.011243209 | L7: =G7/($G$37-$G$35) -> 0.0085330667 | M7: =L7-J7 -> 0.0084330667 | N7: 328.86 | O7: =$F$36/N7-1 -> 0.26877699 | P7: =F7/H7-1 -> -0.28068044 | Q7: =P7-O7 -> -0.54945742 | S7: =TODAY()-I7 -> 479
A8: Financial | B8: =IFERROR(__xludf.DUMMYFUNCTION("IF(GOOGLEFINANCE(D8,""marketcap"")/1000000>10000,""Large Cap"",IF(GOOGLEFINANCE(D8,""marketcap"")/1000000>2000,""Mid Cap"",""Small Cap""))"),"Large Cap") -> Large Cap | C8: =IFERROR(__xludf.DUMMYFUNCTION("GOOGLEFINANCE(D8,""Name"")"),"Berkshire Hathaway Inc Class B") -> Berkshire Hathaway Inc Class B | D8: BRK.B | E8: 96 | F8: =IFERROR(__xludf.DUMMYFUNCTION("GOOGLEFINANCE(D8,""price"")"),498.66) -> 498.66 | G8: =F8*E8 -> 47871.36 | H8: 458.05 | I8: 45590 | J8: 0.0149 | K8: =G8/($G$37-$G$36-$G$35) -> 0.023312011 | L8: =G8/($G$37-$G$35) -> 0.01769272 | M8: =L8-J8 -> 0.0027927195 | N8: 249.59 | O8: =$F$36/N8-1 -> 0.67174166 | P8: =F8/H8-1 -> 0.088658443 | Q8: =P8-O8 -> -0.58308321 | S8: =TODAY()-I8 -> 609
A9: Financial | B9: =IFERROR(__xludf.DUMMYFUNCTION("IF(GOOGLEFINANCE(D9,""marketcap"")/1000000>10000,""Large Cap"",IF(GOOGLEFINANCE(D9,""marketcap"")/1000000>2000,""Mid Cap"",""Small Cap""))"),"Large Cap") -> Large Cap | C9: =IFERROR(__xludf.DUMMYFUNCTION("GOOGLEFINANCE(D9,""Name"")"),"Citigroup Inc") -> Citigroup Inc | D9: C | E9: 1001.5849 | F9: =IFERROR(__xludf.DUMMYFUNCTION("GOOGLEFINANCE(D9,""price"")"),141.76) -> 141.76 | G9: =F9*E9 -> 141984.68 | H9: 44.32 | I9: 45079 | J9: 0.0022 | K9: =G9/($G$37-$G$36-$G$35) -> 0.069142559 | L9: =G9/($G$37-$G$35) -> 0.052475949 | M9: =L9-J9 -> 0.050275949 | N9: 245.26 | O9: =$F$36/N9-1 -> 0.70125581 | P9: =F9/H9-1 -> 2.198556 | Q9: =P9-O9 -> 1.4973001 | S9: =TODAY()-I9 -> 1120
A10: IME | B10: =IFERROR(__xludf.DUMMYFUNCTION("IF(GOOGLEFINANCE(D10,""marketcap"")/1000000>10000,""Large Cap"",IF(GOOGLEFINANCE(D10,""marketcap"")/1000000>2000,""Mid Cap"",""Small Cap""))"),"Large Cap") -> Large Cap | C10: =IFERROR(__xludf.DUMMYFUNCTION("GOOGLEFINANCE(D10,""Name"")"),"CACI INTERNATIONAL INC Common Stock") -> CACI INTERNATIONAL INC Common Stock | D10: CACI | E10: 124 | F10: =IFERROR(__xludf.DUMMYFUNCTION("GOOGLEFINANCE(D10,""price"")"),453.92) -> 453.92 | G10: =F10*E10 -> 56286.08 | H10: 306.87 | I10: 45621 | J10: 0.0002 | K10: =G10/($G$37-$G$36-$G$35) -> 0.027409744 | L10: =G10/($G$37-$G$35) -> 0.020802706 | M10: =L10-J10 -> 0.020602706 | N10: 344 | O10: =$F$36/N10-1 -> 0.21293605 | P10: =F10/H10-1 -> 0.47919314 | Q10: =P10-O10 -> 0.2662571 | S10: =TODAY()-I10 -> 578
A11: TMT | B11: =IFERROR(__xludf.DUMMYFUNCTION("IF(GOOGLEFINANCE(D11,""marketcap"")/1000000>10000,""Large Cap"",IF(GOOGLEFINANCE(D11,""marketcap"")/1000000>2000,""Mid Cap"",""Small Cap""))"),"Large Cap") -> Large Cap | C11: =IFERROR(__xludf.DUMMYFUNCTION("GOOGLEFINANCE(D11,""Name"")"),"Cisco Systems Inc") -> Cisco Systems Inc | D11: CSCO | E11: 670.4639 | F11: =IFERROR(__xludf.DUMMYFUNCTION("GOOGLEFINANCE(D11,""price"")"),113.77) -> 113.77 | G11: =F11*E11 -> 76278.678 | H11: 45.62 | I11: 44708 | J11: 0.004 | K11: =G11/($G$37-$G$36-$G$35) -> 0.037145579 | L11: =G11/($G$37-$G$35) -> 0.028191747 | M11: =L11-J11 -> 0.024191747 | N11: 240.06 | O11: =$F$36/N11-1 -> 0.73810714 | P11: =F11/H11-1 -> 1.4938623 | Q11: =P11-O11 -> 0.7557552 | R11: Winter 24 | S11: =TODAY()-I11 -> 1491
A12: IME | B12: =IFERROR(__xludf.DUMMYFUNCTION("IF(GOOGLEFINANCE(D12,""marketcap"")/1000000>10000,""Large Cap"",IF(GOOGLEFINANCE(D12,""marketcap"")/1000000>2000,""Mid Cap"",""Small Cap""))"),"Large Cap") -> Large Cap | C12: =IFERROR(__xludf.DUMMYFUNCTION("GOOGLEFINANCE(D12,""Name"")"),"Corteva Inc") -> Corteva Inc | D12: CTVA | E12: 763.0004 | F12: =IFERROR(__xludf.DUMMYFUNCTION("GOOGLEFINANCE(D12,""price"")"),82.62) -> 82.62 | G12: =F12*E12 -> 63039.093 | H12: 47.46 | I12: 45446 | J12: 0.0008 | K12: =G12/($G$37-$G$36-$G$35) -> 0.030698272 | L12: =G12/($G$37-$G$35) -> 0.023298544 | M12: =L12-J12 -> 0.022498544 | N12: 300.5 | O12: =$F$36/N12-1 -> 0.38851913 | P12: =F12/H12-1 -> 0.74083439 | Q12: =P12-O12 -> 0.35231525 | S12: =TODAY()-I12 -> 753
A13: Healthcare | B13: =IFERROR(__xludf.DUMMYFUNCTION("IF(GOOGLEFINANCE(D13,""marketcap"")/1000000>10000,""Large Cap"",IF(GOOGLEFINANCE(D13,""marketcap"")/1000000>2000,""Mid Cap"",""Small Cap""))"),"Large Cap") -> Large Cap | C13: =IFERROR(__xludf.DUMMYFUNCTION("GOOGLEFINANCE(D13,""Name"")"),"CVS Health Corp") -> CVS Health Corp | D13: CVS | E13: 774.4222 | F13: 54.85 | G13: =F13*E13 -> 42477.058 | H13: 70.68 | I13: 45446 | J13: 0.0013 | K13: =G13/($G$37-$G$36-$G$35) -> 0.020685137 | L13: =G13/($G$37-$G$35) -> 0.015699046 | M13: =L13-J13 -> 0.014399046 | N13: 300.5 | O13: =$F$36/N13-1 -> 0.38851913 | P13: =F13/H13-1 -> -0.22396718 | Q13: =P13-O13 -> -0.61248631 | S13: =TODAY()-I13 -> 753
A14: IME | B14: =IFERROR(__xludf.DUMMYFUNCTION("IF(GOOGLEFINANCE(D14,""marketcap"")/1000000>10000,""Large Cap"",IF(GOOGLEFINANCE(D14,""marketcap"")/1000000>2000,""Mid Cap"",""Small Cap""))"),"Large Cap") -> Large Cap | C14: =IFERROR(__xludf.DUMMYFUNCTION("GOOGLEFINANCE(D14,""Name"")"),"Chevron Corp") -> Chevron Corp | D14: CVX | E14: 243.3386 | F14: =IFERROR(__xludf.DUMMYFUNCTION("GOOGLEFINANCE(D14,""price"")"),171.06) -> 171.06 | G14: =F14*E14 -> 41625.501 | H14: 143.84 | I14: 45632 | J14: 0.0007 | K14: =G14/($G$37-$G$36-$G$35) -> 0.020270453 | L14: =G14/($G$37-$G$35) -> 0.01538432 | M14: =L14-J14 -> 0.01468432 | N14: 346.74 | O14: =$F$36/N14-1 -> 0.20335121 | P14: =F14/H14-1 -> 0.18923804 | Q14: =P14-O14 -> -0.014113172 | S14: =TODAY()-I14 -> 567
A15: IME | B15: =IFERROR(__xludf.DUMMYFUNCTION("IF(GOOGLEFINANCE(D15,""marketcap"")/1000000>10000,""Large Cap"",IF(GOOGLEFINANCE(D15,""marketcap"")/1000000>2000,""Mid Cap"",""Small Cap""))"),"Large Cap") -> Large Cap | C15: =IFERROR(__xludf.DUMMYFUNCTION("GOOGLEFINANCE(D15,""Name"")"),"Delta Air Lines Inc") -> Delta Air Lines Inc | D15: DAL | E15: 708.9394 | F15: =IFERROR(__xludf.DUMMYFUNCTION("GOOGLEFINANCE(D15,""price"")"),92.57) -> 92.57 | G15: =F15*E15 -> 65626.52 | H15: 34.47 | I15: 44883 | J15: 0.0006 | K15: =G15/($G$37-$G$36-$G$35) -> 0.031958277 | L15: =G15/($G$37-$G$35) -> 0.024254828 | M15: =L15-J15 -> 0.023654828 | N15: 228.94 | O15: =$F$36/N15-1 -> 0.82252992 | P15: =F15/H15-1 -> 1.6855236 | Q15: =P15-O15 -> 0.86299372 | R15: Spring 25 | S15: =TODAY()-I15 -> 1316
A16: Consumer | B16: =IFERROR(__xludf.DUMMYFUNCTION("IF(GOOGLEFINANCE(D16,""marketcap"")/1000000>10000,""Large Cap"",IF(GOOGLEFINANCE(D16,""marketcap"")/1000000>2000,""Mid Cap"",""Small Cap""))"),"Large Cap") -> Large Cap | C16: =IFERROR(__xludf.DUMMYFUNCTION("GOOGLEFINANCE(D16,""Name"")"),"Dollar General Corp") -> Dollar General Corp | D16: DG | E16: 297.41 | F16: =IFERROR(__xludf.DUMMYFUNCTION("GOOGLEFINANCE(D16,""price"")"),119.51) -> 119.51 | G16: =F16*E16 -> 35543.469 | H16: 100.98 | I16: 45804 | J16: 0.0004 | K16: =G16/($G$37-$G$36-$G$35) -> 0.017308674 | L16: =G16/($G$37-$G$35) -> 0.013136469 | M16: =L16-J16 -> 0.012736469 | N16: 336 | O16: =$F$36/N16-1 -> 0.24181548 | P16: =F16/H16-1 -> 0.18350168 | Q16: =P16-O16 -> -0.058313793 | R16: Spring 25 | S16: =TODAY()-I16 -> 395
A17: Financial | B17: =IFERROR(__xludf.DUMMYFUNCTION("IF(GOOGLEFINANCE(D17,""marketcap"")/1000000>10000,""Large Cap"",IF(GOOGLEFINANCE(D17,""marketcap"")/1000000>2000,""Mid Cap"",""Small Cap""))"),"Large Cap") -> Large Cap | C17: =IFERROR(__xludf.DUMMYFUNCTION("GOOGLEFINANCE(D17,""Name"")"),"Evercore Inc") -> Evercore Inc | D17: EVR | E17: 241.6099 | F17: =IFERROR(__xludf.DUMMYFUNCTION("GOOGLEFINANCE(D17,""price"")"),342.02) -> 342.02 | G17: =F17*E17 -> 82635.418 | H17: 146.17 | I17: 45257 | J17: 0.0002 | K17: =G17/($G$37-$G$36-$G$35) -> 0.040241133 | L17: =G17/($G$37-$G$35) -> 0.030541127 | M17: =L17-J17 -> 0.030341127 | N17: 259.48 | O17: =$F$36/N17-1 -> 0.60802374 | P17: =F17/H17-1 -> 1.3398782 | Q17: =P17-O17 -> 0.73185448 | S17: =TODAY()-I17 -> 942
A18: IME | B18: Large Cap | C18: General Dynamics Corporation | D18: GD | E18: 83 | F18: =IFERROR(__xludf.DUMMYFUNCTION("GOOGLEFINANCE(D18,""price"")"),346.71) -> 346.71 | G18: =F18*E18 -> 28776.93 | H18: 359.23 | I18: 46042 | J18: 0.0014 | K18: =G18/($G$37-$G$36-$G$35) -> 0.014013559 | L18: =G18/($G$37-$G$35) -> 0.010635632 | M18: =L18-J18 -> 0.0092356316 | N18: 386.36 | O18: =$F$36/N18-1 -> 0.079951341 | P18: =F18/H18-1 -> -0.034852323 | Q18: =P18-O18 -> -0.11480366 | S18: =TODAY()-I18 -> 157
A19: TMT | B19: =IFERROR(__xludf.DUMMYFUNCTION("IF(GOOGLEFINANCE(D19,""marketcap"")/1000000>10000,""Large Cap"",IF(GOOGLEFINANCE(D19,""marketcap"")/1000000>2000,""Mid Cap"",""Small Cap""))"),"Large Cap") -> Large Cap | C19: =IFERROR(__xludf.DUMMYFUNCTION("GOOGLEFINANCE(D19,""Name"")"),"Alphabet Inc Class A") -> Alphabet Inc Class A | D19: GOOGL | E19: 586.2232 | F19: =IFERROR(__xludf.DUMMYFUNCTION("GOOGLEFINANCE(D19,""price"")"),337.39) -> 337.39 | G19: =F19*E19 -> 197785.85 | H19: 119.64 | I19: 44673 | J19: =1.74%+1.48% -> 0.0322 | K19: =G19/($G$37-$G$36-$G$35) -> 0.096316165 | L19: =G19/($G$37-$G$35) -> 0.073099437 | M19: =L19-J19 -> 0.040899437 | N19: 246.89 | O19: =$F$36/N19-1 -> 0.6900239 | P19: =F19/H19-1 -> 1.8200435 | Q19: =P19-O19 -> 1.1300196 | R19: Winter 24 | S19: =TODAY()-I19 -> 1526
A20: Healthcare | B20: =IFERROR(__xludf.DUMMYFUNCTION("IF(GOOGLEFINANCE(D20,""marketcap"")/1000000>10000,""Large Cap"",IF(GOOGLEFINANCE(D20,""marketcap"")/1000000>2000,""Mid Cap"",""Small Cap""))"),"Large Cap") -> Large Cap | C20: =IFERROR(__xludf.DUMMYFUNCTION("GOOGLEFINANCE(D20,""Name"")"),"Iqvia Holdings Inc") -> Iqvia Holdings Inc | D20: IQV | E20: 117 | F20: =IFERROR(__xludf.DUMMYFUNCTION("GOOGLEFINANCE(D20,""price"")"),191.14) -> 191.14 | G20: =F20*E20 -> 22363.38 | H20: 198 | I20: 45072 | J20: 0.0007 | K20: =G20/($G$37-$G$36-$G$35) -> 0.010890339 | L20: =G20/($G$37-$G$35) -> 0.0082652553 | M20: =L20-J20 -> 0.0075652553 | N20: 240.31 | O20: =$F$36/N20-1 -> 0.73629895 | P20: =F20/H20-1 -> -0.034646465 | Q20: =P20-O20 -> -0.77094541 | R20: Spring 25 | S20: =TODAY()-I20 -> 1127
A21: IME | B21: =IFERROR(__xludf.DUMMYFUNCTION("IF(GOOGLEFINANCE(D21,""marketcap"")/1000000>10000,""Large Cap"",IF(GOOGLEFINANCE(D21,""marketcap"")/1000000>2000,""Mid Cap"",""Small Cap""))"),"Mid Cap") -> Mid Cap | C21: =IFERROR(__xludf.DUMMYFUNCTION("GOOGLEFINANCE(D21,""Name"")"),"Kirby Corp") -> Kirby Corp | D21: KEX | E21: 343 | F21: =IFERROR(__xludf.DUMMYFUNCTION("GOOGLEFINANCE(D21,""price"")"),136.78) -> 136.78 | G21: =F21*E21 -> 46915.54 | H21: 110.89 | I21: 45804 | J21: 0.0001 | K21: =G21/($G$37-$G$36-$G$35) -> 0.022846553 | L21: =G21/($G$37-$G$35) -> 0.017339459 | M21: =L21-J21 -> 0.017239459 | N21: 336 | O21: =$F$36/N21-1 -> 0.24181548 | P21: =F21/H21-1 -> 0.23347461 | Q21: =P21-O21 -> -0.0083408617 | S21: =TODAY()-I21 -> 395
A22: Healthcare | B22: =IFERROR(__xludf.DUMMYFUNCTION("IF(GOOGLEFINANCE(D22,""marketcap"")/1000000>10000,""Large Cap"",IF(GOOGLEFINANCE(D22,""marketcap"")/1000000>2000,""Mid Cap"",""Small Cap""))"),"Large Cap") -> Large Cap | C22: =IFERROR(__xludf.DUMMYFUNCTION("GOOGLEFINANCE(D22,""Name"")"),"McKesson Corp") -> McKesson Corp | D22: MCK | E22: 84.4481 | F22: =IFERROR(__xludf.DUMMYFUNCTION("GOOGLEFINANCE(D22,""price"")"),763.51) -> 763.51 | G22: =F22*E22 -> 64476.969 | H22: 573.16 | I22: 45450 | J22: 0.0012 | K22: =G22/($G$37-$G$36-$G$35) -> 0.031398477 | L22: =G22/($G$37-$G$35) -> 0.023829967 | M22: =L22-J22 -> 0.022629967 | N22: 303.23 | O22: =$F$36/N22-1 -> 0.3760182 | P22: =F22/H22-1 -> 0.33210622 | Q22: =P22-O22 -> -0.043911986 | S22: =TODAY()-I22 -> 749
A23: TMT | B23: =IFERROR(__xludf.DUMMYFUNCTION("IF(GOOGLEFINANCE(D23,""marketcap"")/1000000>10000,""Large Cap"",IF(GOOGLEFINANCE(D23,""marketcap"")/1000000>2000,""Mid Cap"",""Small Cap""))"),"Large Cap") -> Large Cap | C23: =IFERROR(__xludf.DUMMYFUNCTION("GOOGLEFINANCE(D23,""Name"")"),"Microsoft Corp") -> Microsoft Corp | D23: MSFT | E23: 197.8271 | F23: =IFERROR(__xludf.DUMMYFUNCTION("GOOGLEFINANCE(D23,""price"")"),372.97) -> 372.97 | G23: =F23*E23 -> 73783.573 | H23: 405 | I23: 45317 | J23: 0.0565 | K23: =G23/($G$37-$G$36-$G$35) -> 0.035930533 | L23: =G23/($G$37-$G$35) -> 0.027269584 | M23: =L23-J23 -> -0.029230416 | N23: 280 | O23: =$F$36/N23-1 -> 0.49017857 | P23: =F23/H23-1 -> -0.07908642 | Q23: =P23-O23 -> -0.56926499 | S23: =TODAY()-I23 -> 882
A24: TMT | B24: =IFERROR(__xludf.DUMMYFUNCTION("IF(GOOGLEFINANCE(D24,""marketcap"")/1000000>10000,""Large Cap"",IF(GOOGLEFINANCE(D24,""marketcap"")/1000000>2000,""Mid Cap"",""Small Cap""))"),"Small Cap") -> Small Cap | C24: =IFERROR(__xludf.DUMMYFUNCTION("GOOGLEFINANCE(D24,""Name"")"),"nCino Inc") -> nCino Inc | D24: NCNO | E24: 1500 | F24: =IFERROR(__xludf.DUMMYFUNCTION("GOOGLEFINANCE(D24,""price"")"),15.63) -> 15.63 | G24: =F24*E24 -> 23445 | H24: 15.15 | I24: 46092 | J24: 0 | K24: =G24/($G$37-$G$36-$G$35) -> 0.011417058 | L24: =G24/($G$37-$G$35) -> 0.0086650099 | M24: =L24-J24 -> 0.0086650099 | N24: 378.23 | O24: =$F$36/N24-1 -> 0.10316474 | P24: =F24/H24-1 -> 0.031683168 | Q24: =P24-O24 -> -0.071481573 | S24: =TODAY()-I24 -> 107
A25: IME | B25: =IFERROR(__xludf.DUMMYFUNCTION("IF(GOOGLEFINANCE(D25,""marketcap"")/1000000>10000,""Large Cap"",IF(GOOGLEFINANCE(D25,""marketcap"")/1000000>2000,""Mid Cap"",""Small Cap""))"),"Large Cap") -> Large Cap | C25: =IFERROR(__xludf.DUMMYFUNCTION("GOOGLEFINANCE(D25,""Name"")"),"NextEra Energy Inc") -> NextEra Energy Inc | D25: NEE | E25: 716.1442 | F25: =IFERROR(__xludf.DUMMYFUNCTION("GOOGLEFINANCE(D25,""price"")"),88.56) -> 88.56 | G25: =F25*E25 -> 63421.73 | H25: 51.99 | I25: 45211 | J25: 0.003 | K25: =G25/($G$37-$G$36-$G$35) -> 0.030884606 | L25: =G25/($G$37-$G$35) -> 0.023439963 | M25: =L25-J25 -> 0.020439963 | N25: 247.8 | O25: =$F$36/N25-1 -> 0.68381759 | P25: =F25/H25-1 -> 0.7034045 | Q25: =P25-O25 -> 0.019586906 | S25: =TODAY()-I25 -> 988
A26: TMT | B26: =IFERROR(__xludf.DUMMYFUNCTION("IF(GOOGLEFINANCE(D26,""marketcap"")/1000000>10000,""Large Cap"",IF(GOOGLEFINANCE(D26,""marketcap"")/1000000>2000,""Mid Cap"",""Small Cap""))"),"Large Cap") -> Large Cap | C26: =IFERROR(__xludf.DUMMYFUNCTION("GOOGLEFINANCE(D26,""Name"")"),"Omnicom Group Inc") -> Omnicom Group Inc | D26: OMC | E26: 419.1691 | F26: =IFERROR(__xludf.DUMMYFUNCTION("GOOGLEFINANCE(D26,""price"")"),73.09) -> 73.09 | G26: =F26*E26 -> 30637.07 | H26: 78.39 | I26: 45446 | J26: 0.0004 | K26: =G26/($G$37-$G$36-$G$35) -> 0.014919394 | L26: =G26/($G$37-$G$35) -> 0.011323118 | M26: =L26-J26 -> 0.010923118 | N26: 300.5 | O26: =$F$36/N26-1 -> 0.38851913 | P26: =F26/H26-1 -> -0.067610665 | Q26: =P26-O26 -> -0.4561298 | S26: =TODAY()-I26 -> 753
A27: Healthcare | B27: =IFERROR(__xludf.DUMMYFUNCTION("IF(GOOGLEFINANCE(D27,""marketcap"")/1000000>10000,""Large Cap"",IF(GOOGLEFINANCE(D27,""marketcap"")/1000000>2000,""Mid Cap"",""Small Cap""))"),"Large Cap") -> Large Cap | C27: =IFERROR(__xludf.DUMMYFUNCTION("GOOGLEFINANCE(D27,""Name"")"),"Pfizer Inc") -> Pfizer Inc | D27: PFE | E27: 908.8086 | F27: =IFERROR(__xludf.DUMMYFUNCTION("GOOGLEFINANCE(D27,""price"")"),24.29) -> 24.29 | G27: =F27*E27 -> 22074.961 | H27: 27.5 | I27: 45331 | J27: 0.0029 | K27: =G27/($G$37-$G$36-$G$35) -> 0.010749887 | L27: =G27/($G$37-$G$35) -> 0.0081586588 | M27: =L27-J27 -> 0.0052586588 | N27: 284 | O27: =$F$36/N27-1 -> 0.46919014 | P27: =F27/H27-1 -> -0.11672727 | Q27: =P27-O27 -> -0.58591741 | S27: =TODAY()-I27 -> 868
A28: Healthcare | B28: =IFERROR(__xludf.DUMMYFUNCTION("IF(GOOGLEFINANCE(D28,""marketcap"")/1000000>10000,""Large Cap"",IF(GOOGLEFINANCE(D28,""marketcap"")/1000000>2000,""Mid Cap"",""Small Cap""))"),"Large Cap") -> Large Cap | C28: =IFERROR(__xludf.DUMMYFUNCTION("GOOGLEFINANCE(D28,""Name"")"),"Regeneron Pharmaceuticals Inc") -> Regeneron Pharmaceuticals Inc | D28: REGN | E28: 25.1458 | F28: =IFERROR(__xludf.DUMMYFUNCTION("GOOGLEFINANCE(D28,""price"")"),632.9) -> 632.9 | G28: =F28*E28 -> 15914.777 | H28: 741.48 | I28: 44893 | J28: 0.0017 | K28: =G28/($G$37-$G$36-$G$35) -> 0.0077500504 | L28: =G28/($G$37-$G$35) -> 0.0058819236 | M28: =L28-J28 -> 0.0041819236 | N28: 228.69 | O28: =$F$36/N28-1 -> 0.82452228 | P28: =F28/H28-1 -> -0.14643686 | Q28: =P28-O28 -> -0.97095914 | R28: Winter 24 | S28: =TODAY()-I28 -> 1306
A29: Consumer | B29: =IFERROR(__xludf.DUMMYFUNCTION("IF(GOOGLEFINANCE(D29,""marketcap"")/1000000>10000,""Large Cap"",IF(GOOGLEFINANCE(D29,""marketcap"")/1000000>2000,""Mid Cap"",""Small Cap""))"),"Large Cap") -> Large Cap | C29: =IFERROR(__xludf.DUMMYFUNCTION("GOOGLEFINANCE(D29,""Name"")"),"J.M. Smucker Co") -> J.M. Smucker Co | D29: SJM | E29: 306.9374 | F29: =IFERROR(__xludf.DUMMYFUNCTION("GOOGLEFINANCE(D29,""price"")"),115.64) -> 115.64 | G29: =F29*E29 -> 35494.241 | H29: 111.42 | I29: 45261 | J29: 0.0002 | K29: =G29/($G$37-$G$36-$G$35) -> 0.017284701 | L29: =G29/($G$37-$G$35) -> 0.013118275 | M29: =L29-J29 -> 0.012918275 | N29: 263.04 | O29: =$F$36/N29-1 -> 0.58626064 | P29: =F29/H29-1 -> 0.037874708 | Q29: =P29-O29 -> -0.54838594 | S29: =TODAY()-I29 -> 938
A30: Financial | B30: =IFERROR(__xludf.DUMMYFUNCTION("IF(GOOGLEFINANCE(D30,""marketcap"")/1000000>10000,""Large Cap"",IF(GOOGLEFINANCE(D30,""marketcap"")/1000000>2000,""Mid Cap"",""Small Cap""))"),"Large Cap") -> Large Cap | C30: =IFERROR(__xludf.DUMMYFUNCTION("GOOGLEFINANCE(D30,""Name"")"),"S&P Global Inc") -> S&P Global Inc | D30: SPGI | E30: 95.8905 | F30: =IFERROR(__xludf.DUMMYFUNCTION("GOOGLEFINANCE(D30,""price"")"),408.16) -> 408.16 | G30: =F30*E30 -> 39138.666 | H30: 408 | I30: 45250 | J30: 0.0027 | K30: =G30/($G$37-$G$36-$G$35) -> 0.019059434 | L30: =G30/($G$37-$G$35) -> 0.014465214 | M30: =L30-J30 -> 0.011765214 | N30: 259.22 | O30: =$F$36/N30-1 -> 0.6096366 | P30: =F30/H30-1 -> 0.00039215686 | Q30: =P30-O30 -> -0.60924445 | S30: =TODAY()-I30 -> 949
A31: IME | B31: =IFERROR(__xludf.DUMMYFUNCTION("IF(GOOGLEFINANCE(D31,""marketcap"")/1000000>10000,""Large Cap"",IF(GOOGLEFINANCE(D31,""marketcap"")/1000000>2000,""Mid Cap"",""Small Cap""))"),"Large Cap") -> Large Cap | C31: =IFERROR(__xludf.DUMMYFUNCTION("GOOGLEFINANCE(D31,""Name"")"),"Smurfit WestRock PLC") -> Smurfit WestRock PLC | D31: SW | E31: 564 | F31: =IFERROR(__xludf.DUMMYFUNCTION("GOOGLEFINANCE(D31,""price"")"),46.98) -> 46.98 | G31: =F31*E31 -> 26496.72 | H31: 56.64 | I31: 45618 | J31: 0.0005 | K31: =G31/($G$37-$G$36-$G$35) -> 0.01290316 | L31: =G31/($G$37-$G$35) -> 0.0097928915 | M31: =L31-J31 -> 0.0092928915 | N31: 342.28 | O31: =$F$36/N31-1 -> 0.2190312 | P31: =F31/H31-1 -> -0.17055085 | Q31: =P31-O31 -> -0.38958205 | S31: =TODAY()-I31 -> 581
A32: TMT | B32: =IFERROR(__xludf.DUMMYFUNCTION("IF(GOOGLEFINANCE(D32,""marketcap"")/1000000>10000,""Large Cap"",IF(GOOGLEFINANCE(D32,""marketcap"")/1000000>2000,""Mid Cap"",""Small Cap""))"),"Large Cap") -> Large Cap | C32: =IFERROR(__xludf.DUMMYFUNCTION("GOOGLEFINANCE(D32,""Name"")"),"Twilio Inc") -> Twilio Inc | D32: TWLO | E32: 725 | F32: =IFERROR(__xludf.DUMMYFUNCTION("GOOGLEFINANCE(D32,""price"")"),191.57) -> 191.57 | G32: =F32*E32 -> 138888.25 | H32: 53 | I32: 45226 | J32: 0.0002 | K32: =G32/($G$37-$G$36-$G$35) -> 0.067634686 | L32: =G32/($G$37-$G$35) -> 0.051331545 | M32: =L32-J32 -> 0.051131545 | N32: 234.36 | O32: =$F$36/N32-1 -> 0.78038061 | P32: =F32/H32-1 -> 2.6145283 | Q32: =P32-O32 -> 1.8341477 | S32: =TODAY()-I32 -> 973
A33: Healthcare | B33: =IFERROR(__xludf.DUMMYFUNCTION("IF(GOOGLEFINANCE(D33,""marketcap"")/1000000>10000,""Large Cap"",IF(GOOGLEFINANCE(D33,""marketcap"")/1000000>2000,""Mid Cap"",""Small Cap""))"),"Mid Cap") -> Mid Cap | C33: =IFERROR(__xludf.DUMMYFUNCTION("GOOGLEFINANCE(D33,""Name"")"),"Universal Health Services Inc") -> Universal Health Services Inc | D33: UHS | E33: 281.5038 | F33: =IFERROR(__xludf.DUMMYFUNCTION("GOOGLEFINANCE(D33,""price"")"),145.69) -> 145.69 | G33: =F33*E33 -> 41012.289 | H33: 132.13 | I33: 45086 | J33: 0.0002 | K33: =G33/($G$37-$G$36-$G$35) -> 0.019971835 | L33: =G33/($G$37-$G$35) -> 0.015157683 | M33: =L33-J33 -> 0.014957683 | N33: 246.07 | O33: =$F$36/N33-1 -> 0.69565571 | P33: =F33/H33-1 -> 0.1026262 | Q33: =P33-O33 -> -0.59302951 | S33: =TODAY()-I33 -> 1113
A34: Financial | B34: =IFERROR(__xludf.DUMMYFUNCTION("IF(GOOGLEFINANCE(D34,""marketcap"")/1000000>10000,""Large Cap"",IF(GOOGLEFINANCE(D34,""marketcap"")/1000000>2000,""Mid Cap"",""Small Cap""))"),"Large Cap") -> Large Cap | C34: =IFERROR(__xludf.DUMMYFUNCTION("GOOGLEFINANCE(D34,""Name"")"),"UMB Financial Corp") -> UMB Financial Corp | D34: UMBF | E34: 504.499 | F34: =IFERROR(__xludf.DUMMYFUNCTION("GOOGLEFINANCE(D34,""price"")"),144.91) -> 144.91 | G34: =F34*E34 -> 73106.95 | H34: 121.67 | I34: 45204 | J34: 0 | K34: =G34/($G$37-$G$36-$G$35) -> 0.035601036 | L34: =G34/($G$37-$G$35) -> 0.027019512 | M34: =L34-J34 -> 0.027019512 | N34: 347.86 | O34: =$F$36/N34-1 -> 0.1994768 | P34: =F34/H34-1 -> 0.19100847 | Q34: =P34-O34 -> -0.0084683355 | S34: =TODAY()-I34 -> 995
A35: Cash | B35: Cash | C35: Cash | D35: BGNXX | G35: 33.55
A36: Index | B36: Index ETF | C36: =IFERROR(__xludf.DUMMYFUNCTION("GOOGLEFINANCE(D36,""Name"")"),"iShares Russell 3000 ETF") -> iShares Russell 3000 ETF | D36: IWV | E36: =1167.0996+34+129+233 -> 1563.0996 | F36: =IFERROR(__xludf.DUMMYFUNCTION("GOOGLEFINANCE(D36,""price"")"),417.25) -> 417.25 | G36: =F36*E36 -> 652203.31 | H36: =G36/G37 -> 0.24104406
A37: Total | B37: =COUNTA(B2:B34) -> 33 | C37: Holdings # | G37: =SUM($G$2:$G$36) -> 2705743.1
B39: 46115 | C39: Last Updated | E39: avg. position size | F39: =AVERAGE(G8:G34) -> 59151.879
E40: avg. class allocation | F40: =AVERAGE(K8:K34) -> 0.028805308
D42: Sector | E42: Mkt. Cap | F42: New positions | G42: Estimate | H42: Shares | J42: % of portfolio equities | K42: Share Price | M42: Transaction | Q42: Current Position | R42: New Position | S42: Passive Weight | T42: New Class Weight | U42: Old Active Weight | V42: New Active Weight
...

Sheet Alumni Fund
A1: Sector | B1: Capitalization | C1: Name | D1: Ticker | E1: Shares | F1: Price | G1: Market Value | H1: Last Update Price | I1: Last Update Date | J1: Passive Weight | K1: Class Weight | L1: Portfolio Weight | M1: Active Weight | N1: Last Update ETF Price | O1: Market Return Since Update | P1: Return Since Update | Q1: Excess Return Since Update | R1: Update Status | S1: Days Since Update
A2: IME | B2: =IFERROR(__xludf.DUMMYFUNCTION("IF(GOOGLEFINANCE(D2,""marketcap"")/1000000>10000,""Large Cap"",IF(GOOGLEFINANCE(D2,""marketcap"")/1000000>2000,""Mid Cap"",""Small Cap""))"),"Large Cap") -> Large Cap | C2: =IFERROR(__xludf.DUMMYFUNCTION("GOOGLEFINANCE(D2,""Name"")"),"Argan Inc") -> Argan Inc | D2: AGX | E2: 46.7 | F2: =IFERROR(__xludf.DUMMYFUNCTION("GOOGLEFINANCE(D2,""price"")"),765.46) -> 765.46 | G2: =F2*E2 -> 35746.982 | H2: 49.49 | I2: 45359 | J2: 0.0015 | K2: =G2/$G$16 -> 0.22611521 | L2: =G2/($G$15+$G$16) -> 0.080751558 | M2: =L2-J2 -> 0.079251558 | N2: 206.83 | O2: =$F$15/N2-1 -> 0.44964464 | P2: =F2/H2-1 -> 14.466963 | Q2: =P2-O2 -> 14.017318 | S2: =TODAY()-I2 -> 840
A3: Financial | B3: =IFERROR(__xludf.DUMMYFUNCTION("IF(GOOGLEFINANCE(D3,""marketcap"")/1000000>10000,""Large Cap"",IF(GOOGLEFINANCE(D3,""marketcap"")/1000000>2000,""Mid Cap"",""Small Cap""))"),"Mid Cap") -> Mid Cap | C3: =IFERROR(__xludf.DUMMYFUNCTION("GOOGLEFINANCE(D3,""Name"")"),"Axos Financial Inc") -> Axos Financial Inc | D3: AX | E3: 166 | F3: =IFERROR(__xludf.DUMMYFUNCTION("GOOGLEFINANCE(D3,""price"")"),96.23) -> 96.23 | G3: =F3*E3 -> 15974.18 | H3: 41.58 | I3: 44946 | J3: 0.0017 | K3: =G3/$G$16 -> 0.10104363 | L3: =G3/($G$15+$G$16) -> 0.036085282 | M3: =L3-J3 -> 0.034385282 | N3: 185.04 | O3: =$F$15/N3-1 -> 0.62035236 | P3: =F3/H3-1 -> 1.3143338 | Q3: =P3-O3 -> 0.69398146 | R3: Winter 24? | S3: =TODAY()-I3 -> 1253
A4: IME | B4: =IFERROR(__xludf.DUMMYFUNCTION("IF(GOOGLEFINANCE(D4,""marketcap"")/1000000>10000,""Large Cap"",IF(GOOGLEFINANCE(D4,""marketcap"")/1000000>2000,""Mid Cap"",""Small Cap""))"),"Mid Cap") -> Mid Cap | C4: =IFERROR(__xludf.DUMMYFUNCTION("GOOGLEFINANCE(D4,""Name"")"),"Blue Bird Corp") -> Blue Bird Corp | D4: BLBD | E4: 316 | F4: =IFERROR(__xludf.DUMMYFUNCTION("GOOGLEFINANCE(D4,""price"")"),78.81) -> 78.81 | G4: =F4*E4 -> 24903.96 | H4: 20.59 | I4: 45204 | J4: 0.0005 | K4: =G4/$G$16 -> 0.15752838 | L4: =G4/($G$15+$G$16) -> 0.056257437 | M4: =L4-J4 -> 0.055757437 | N4: 171.35 | O4: =$F$15/N4-1 -> 0.74981033 | P4: =F4/H4-1 -> 2.8275862 | Q4: =P4-O4 -> 2.0777759 | S4: =TODAY()-I4 -> 995
A5: Healthcare | B5: =IFERROR(__xludf.DUMMYFUNCTION("IF(GOOGLEFINANCE(D5,""marketcap"")/1000000>10000,""Large Cap"",IF(GOOGLEFINANCE(D5,""marketcap"")/1000000>2000,""Mid Cap"",""Small Cap""))"),"Mid Cap") -> Mid Cap | C5: =IFERROR(__xludf.DUMMYFUNCTION("GOOGLEFINANCE(D5,""Name"")"),"Concentra Group Holdings Parent Inc") -> Concentra Group Holdings Parent Inc | D5: CON | E5: 45.5 | F5: =IFERROR(__xludf.DUMMYFUNCTION("GOOGLEFINANCE(D5,""price"")"),30.18) -> 30.18 | G5: =F5*E5 -> 1373.19 | H5: 20.59 | I5: 45572 | J5: 0.0008 | K5: =G5/$G$16 -> 0.0086860239 | L5: =G5/($G$15+$G$16) -> 0.0031020026 | M5: =L5-J5 -> 0.0023020026 | N5: 221.85 | O5: =$F$15/N5-1 -> 0.35149876 | P5: =F5/H5-1 -> 0.46576008 | Q5: =P5-O5 -> 0.11426132 | S5: =TODAY()-I5 -> 627
A6: Healthcare | B6: =IFERROR(__xludf.DUMMYFUNCTION("IF(GOOGLEFINANCE(D6,""marketcap"")/1000000>10000,""Large Cap"",IF(GOOGLEFINANCE(D6,""marketcap"")/1000000>2000,""Mid Cap"",""Small Cap""))"),"Mid Cap") -> Mid Cap | C6: =IFERROR(__xludf.DUMMYFUNCTION("GOOGLEFINANCE(D6,""Name"")"),"Catalyst Pharmaceuticals Inc") -> Catalyst Pharmaceuticals Inc | D6: CPRX | E6: 550 | F6: =IFERROR(__xludf.DUMMYFUNCTION("GOOGLEFINANCE(D6,""price"")"),31.5) -> 31.5 | G6: =F6*E6 -> 17325 | H6: 12.99 | I6: 45236 | J6: 0.0009 | K6: =G6/$G$16 -> 0.10958816 | L6: =G6/($G$15+$G$16) -> 0.039136751 | M6: =L6-J6 -> 0.038236751 | N6: 172.31 | O6: =$F$15/N6-1 -> 0.74006152 | P6: =F6/H6-1 -> 1.4249423 | Q6: =P6-O6 -> 0.68488075 | R6: Spring 25 | S6: =TODAY()-I6 -> 963
A7: Financial | B7: =IFERROR(__xludf.DUMMYFUNCTION("IF(GOOGLEFINANCE(D7,""marketcap"")/1000000>10000,""Large Cap"",IF(GOOGLEFINANCE(D7,""marketcap"")/1000000>2000,""Mid Cap"",""Small Cap""))"),"Mid Cap") -> Mid Cap | C7: =IFERROR(__xludf.DUMMYFUNCTION("GOOGLEFINANCE(D7,""Name"")"),"Caretrust REIT Inc") -> Caretrust REIT Inc | D7: CTRE | E7: 393.5 | F7: =IFERROR(__xludf.DUMMYFUNCTION("GOOGLEFINANCE(D7,""price"")"),40.83) -> 40.83 | G7: =F7*E7 -> 16066.605 | H7: 28.64 | I7: 45790 | J7: 0.0027 | K7: =G7/$G$16 -> 0.10162826 | L7: =G7/($G$15+$G$16) -> 0.036294068 | M7: =L7-J7 -> 0.033594068 | N7: 208.63 | O7: =$F$15/N7-1 -> 0.43713752 | P7: =F7/H7-1 -> 0.42562849 | Q7: =P7-O7 -> -0.011509025 | S7: =TODAY()-I7 -> 409
A8: Financial | B8: =IFERROR(__xludf.DUMMYFUNCTION("IF(GOOGLEFINANCE(D8,""marketcap"")/1000000>10000,""Large Cap"",IF(GOOGLEFINANCE(D8,""marketcap"")/1000000>2000,""Mid Cap"",""Small Cap""))"),"Small Cap") -> Small Cap | C8: =IFERROR(__xludf.DUMMYFUNCTION("GOOGLEFINANCE(D8,""Name"")"),"Forestar Group Inc") -> Forestar Group Inc | D8: FOR | E8: 100 | F8: =IFERROR(__xludf.DUMMYFUNCTION("GOOGLEFINANCE(D8,""price"")"),31.94) -> 31.94 | G8: =F8*E8 -> 3194 | H8: 29.23 | I8: 45611 | J8: 0.0002 | K8: =G8/$G$16 -> 0.020203439 | L8: =G8/($G$15+$G$16) -> 0.0072151679 | M8: =L8-J8 -> 0.0070151679 | N8: 234.05 | O8: =$F$15/N8-1 -> 0.28105106 | P8: =F8/H8-1 -> 0.092712966 | Q8: =P8-O8 -> -0.18833809 | S8: =TODAY()-I8 -> 588
A9: IME | B9: =IFERROR(__xludf.DUMMYFUNCTION("IF(GOOGLEFINANCE(D9,""marketcap"")/1000000>10000,""Large Cap"",IF(GOOGLEFINANCE(D9,""marketcap"")/1000000>2000,""Mid Cap"",""Small Cap""))"),"Mid Cap") -> Mid Cap | C9: =IFERROR(__xludf.DUMMYFUNCTION("GOOGLEFINANCE(D9,""Name"")"),"Centrus Energy Corp") -> Centrus Energy Corp | D9: LEU | E9: 45 | F9: =IFERROR(__xludf.DUMMYFUNCTION("GOOGLEFINANCE(D9,""price"")"),165.52) -> 165.52 | G9: =F9*E9 -> 7448.4 | H9: 38.25 | I9: 45366 | J9: 0.0015 | K9: =G9/$G$16 -> 0.047114369 | L9: =G9/($G$15+$G$16) -> 0.016825753 | M9: =L9-J9 -> 0.015325753 | N9: 202.45 | O9: =$F$15/N9-1 -> 0.48100766 | P9: =F9/H9-1 -> 3.3273203 | Q9: =P9-O9 -> 2.8463126 | S9: =TODAY()-I9 -> 833
A10: Healthcare | B10: =IFERROR(__xludf.DUMMYFUNCTION("IF(GOOGLEFINANCE(D10,""marketcap"")/1000000>10000,""Large Cap"",IF(GOOGLEFINANCE(D10,""marketcap"")/1000000>2000,""Mid Cap"",""Small Cap""))"),"Small Cap") -> Small Cap | C10: Omnicell, Inc. | D10: OMCL | E10: 303 | F10: =IFERROR(__xludf.DUMMYFUNCTION("GOOGLEFINANCE(D10,""price"")"),40.13) -> 40.13 | G10: =F10*E10 -> 12159.39 | H10: 39.57 | I10: 45982 | J10: 0.0007 | K10: =G10/$G$16 -> 0.076913429 | L10: =G10/($G$15+$G$16) -> 0.027467765 | M10: =L10-J10 -> 0.026767765 | N10: 235.6 | O10: =$F$15/N10-1 -> 0.27262309 | P10: =F10/H10-1 -> 0.014152135 | Q10: =P10-O10 -> -0.25847095 | S10: =TODAY()-I10 -> 217
A11: TMT | B11: =IFERROR(__xludf.DUMMYFUNCTION("IF(GOOGLEFINANCE(D11,""marketcap"")/1000000>10000,""Large Cap"",IF(GOOGLEFINANCE(D11,""marketcap"")/1000000>2000,""Mid Cap"",""Small Cap""))"),"Small Cap") -> Small Cap | C11: =IFERROR(__xludf.DUMMYFUNCTION("GOOGLEFINANCE(D11,""Name"")"),"Progress Software Corp") -> Progress Software Corp | D11: PRGS | E11: 209 | F11: =IFERROR(__xludf.DUMMYFUNCTION("GOOGLEFINANCE(D11,""price"")"),33.15) -> 33.15 | G11: =F11*E11 -> 6928.35 | H11: 57.5 | I11: 45310 | J11: 0.0006 | K11: =G11/$G$16 -> 0.043824826 | L11: =G11/($G$15+$G$16) -> 0.015650973 | M11: =L11-J11 -> 0.015050973 | N11: 192.4 | O11: =$F$15/N11-1 -> 0.55836798 | P11: =F11/H11-1 -> -0.42347826 | Q11: =P11-O11 -> -0.98184624 | S11: =TODAY()-I11 -> 889
A12: Healthcare | B12: =IFERROR(__xludf.DUMMYFUNCTION("IF(GOOGLEFINANCE(D12,""marketcap"")/1000000>10000,""Large Cap"",IF(GOOGLEFINANCE(D12,""marketcap"")/1000000>2000,""Mid Cap"",""Small Cap""))"),"Mid Cap") -> Mid Cap | C12: =IFERROR(__xludf.DUMMYFUNCTION("GOOGLEFINANCE(D12,""Name"")"),"Select Medical Holdings Corp") -> Select Medical Holdings Corp | D12: SEM | E12: 56.9 | F12: =IFERROR(__xludf.DUMMYFUNCTION("GOOGLEFINANCE(D12,""price"")"),16.5) -> 16.5 | G12: =F12*E12 -> 938.85 | H12: 33.09 | I12: 45572 | J12: 0.0005 | K12: =G12/$G$16 -> 0.0059386345 | L12: =G12/($G$15+$G$16) -> 0.0021208392 | M12: =L12-J12 -> 0.0016208392 | N12: 221.85 | O12: =$F$15/N12-1 -> 0.35149876 | P12: =F12/H12-1 -> -0.50135993 | Q12: =P12-O12 -> -0.85285869 | S12: =TODAY()-I12 -> 627
A13: Financial | B13: =IFERROR(__xludf.DUMMYFUNCTION("IF(GOOGLEFINANCE(D13,""marketcap"")/1000000>10000,""Large Cap"",IF(GOOGLEFINANCE(D13,""marketcap"")/1000000>2000,""Mid Cap"",""Small Cap""))"),"Large Cap") -> Large Cap | C13: =IFERROR(__xludf.DUMMYFUNCTION("GOOGLEFINANCE(D13,""Name"")"),"UMB Financial Corp") -> UMB Financial Corp | D13: UMBF | E13: 75.1 | F13: =IFERROR(__xludf.DUMMYFUNCTION("GOOGLEFINANCE(D13,""price"")"),144.91) -> 144.91 | G13: =F13*E13 -> 10882.741 | H13: 121.67 | I13: 45204 | J13: 0.0029 | K13: =G13/$G$16 -> 0.068838069 | L13: =G13/($G$15+$G$16) -> 0.024583846 | M13: =L13-J13 -> 0.021683846 | N13: 229.63 | O13: =$F$15/N13-1 -> 0.30570918 | P13: =F13/H13-1 -> 0.19100847 | Q13: =P13-O13 -> -0.11470072 | S13: =TODAY()-I13 -> 995
A14: TMT | B14: Mid Cap | C14: Workiva Inc | D14: WK | E14: 105 | F14: =IFERROR(__xludf.DUMMYFUNCTION("GOOGLEFINANCE(D14,""price"")"),49.05) -> 49.05 | G14: =F14*E14 -> 5150.25 | H14: 88.37 | I14: 45971 | J14: 0.0013 | K14: =G14/$G$16 -> 0.032577571 | L14: =G14/($G$15+$G$16) -> 0.011634289 | M14: =L14-J14 -> 0.010334289 | N14: 244.03 | O14: =$F$15/N14-1 -> 0.22866041 | P14: =F14/H14-1 -> -0.44494738 | Q14: =P14-O14 -> -0.67360779 | S14: =TODAY()-I14 -> 228
A15: Index ETF | B15: Index ETF | C15: =IFERROR(__xludf.DUMMYFUNCTION("GOOGLEFINANCE(D15,""Name"")"),"iShares Russell 2000 ETF") -> iShares Russell 2000 ETF | D15: IWM | E15: =879.16+70 -> 949.16 | F15: =IFERROR(__xludf.DUMMYFUNCTION("GOOGLEFINANCE(D15,""price"")"),299.83) -> 299.83 | G15: =E15*F15 -> 284586.64 | H15: =G15/G18 -> 0.64254101 | K15: =G15/$G$18 -> 0.64254101 | M15: =AVERAGE(M2:M14) -> 0.026255826
A16: Equity Values | G16: =SUM(G2:G14) -> 158091.9
A17: Cash | B17: Cash | C17: Cash | D17: BNGXX | G17: 229.6
A18: Total | B18: =COUNTA(B2:B14) -> 13 | C18: Holdings # | G18: =SUM(G$15:G17) -> 442908.14
E20: avg. position size | F20: =AVERAGE(G2:G12) -> 12914.446 | M20: =AVERAGE(M2:M12) -> 0.028118873
B21: 46093 | C21: Last Updated | E21: avg. allocation | F21: =AVERAGE(K2:K12) -> 0.081689487
D23: Sector | E23: Mkt Cap | F23: New positions | G23: Estimate | H23: Shares | J23: % of portfolio equities | K23: Share Price | M23: Transaction | Q23: Current Position | R23: New Position | S23: Passive Weight | T23: New Class Weight | U23: Old Active Weight | V23: New Active Weight
D24: TMT | E24: =IFERROR(__xludf.DUMMYFUNCTION("iferror(IF(GOOGLEFINANCE(F24,""marketcap"")/1000000>10000,""Large Cap"",IF(GOOGLEFINANCE(F24,""marketcap"")/1000000>2000,""Mid Cap"",""Small Cap"")),"""")"),"") | G24: =J24*($G$18-$G$17-$G$15) -> 15809.19 | H24: =IFERROR(ROUND(G24/K24,0), 0) -> 0 | J24: 0.1 | K24: =IFERROR(__xludf.DUMMYFUNCTION("IFERROR(GOOGLEFINANCE(F24,""price""), 0)"),0) -> 0 | M24: =K24*H24 -> 0 | Q24: =IFERROR(VLOOKUP(F24,$D$2:$R$17,4,FALSE), 0) -> 0 | R24: =M24+IFERROR(Q24,0) -> 0 | T24: =R24/($G$18-($G$17-$M$36+$M$37)-$G$15) -> 0 | U24: =IFERROR(VLOOKUP(F24,$D$2:$R$37,8,FALSE),0) -> 0 | V24: =T24-S24 -> 0
E25: =IFERROR(__xludf.DUMMYFUNCTION("iferror(IF(GOOGLEFINANCE(F25,""marketcap"")/1000000>10000,""Large Cap"",IF(GOOGLEFINANCE(F25,""marketcap"")/1000000>2000,""Mid Cap"",""Small Cap"")),"""")"),"") | G25: =J25*($G$18-$G$17-$G$15) -> 0 | H25: =IFERROR(ROUND(G25/K25,0), 0) -> 0 | K25: =IFERROR(__xludf.DUMMYFUNCTION("IFERROR(GOOGLEFINANCE(F25,""price""), 0)"),0) -> 0 | M25: =K25*H25 -> 0 | Q25: =IFERROR(VLOOKUP(F25,$D$2:$R$17,4,FALSE), 0) -> 0 | R25: =M25+IFERROR(#REF!,0) -> 0 | S25: 0 | T25: =R25/($G$18-($G$17-$M$36+$M$37)-$G$15) -> 0 | U25: =IFERROR(VLOOKUP(F25,$D$2:$R$18,8,FALSE),0) -> 0 | V25: =(R25/($G$18-$G$17-$G$15)-S25) -> 0
E26: =IFERROR(__xludf.DUMMYFUNCTION("iferror(IF(GOOGLEFINANCE(F26,""marketcap"")/1000000>10000,""Large Cap"",IF(GOOGLEFINANCE(F26,""marketcap"")/1000000>2000,""Mid Cap"",""Small Cap"")),"""")"),"") | G26: =J26*($G$18-$G$17-$G$15) -> 0 | H26: =IFERROR(ROUND(G26/K26,0), 0) -> 0 | K26: =IFERROR(__xludf.DUMMYFUNCTION("IFERROR(GOOGLEFINANCE(F26,""price""), 0)"),0) -> 0 | M26: =K26*H26 -> 0 | Q26: =IFERROR(VLOOKUP(F26,$D$2:$R$17,4,FALSE), 0) -> 0 | R26: =M26+IFERROR(#REF!,0) -> 0 | S26: 0 | T26: =R26/($G$18-($G$17-$M$36+$M$37)-$G$15) -> 0 | U26: =IFERROR(VLOOKUP(F26,$D$2:$R$18,8,FALSE),0) -> 0 | V26: =(R26/($G$18-$G$17-$G$15)-S26) -> 0
E27: =IFERROR(__xludf.DUMMYFUNCTION("iferror(IF(GOOGLEFINANCE(F27,""marketcap"")/1000000>10000,""Large Cap"",IF(GOOGLEFINANCE(F27,""marketcap"")/1000000>2000,""Mid Cap"",""Small Cap"")),"""")"),"") | G27: =J27*($G$18-$G$17-$G$15) -> 0 | H27: =IFERROR(ROUND(G27/K27,0), 0) -> 0 | K27: =IFERROR(__xludf.DUMMYFUNCTION("IFERROR(GOOGLEFINANCE(F27,""price""), 0)"),0) -> 0 | M27: =K27*H27 -> 0 | Q27: =IFERROR(VLOOKUP(F27,$D$2:$R$17,4,FALSE), 0) -> 0 | R27: =M27+IFERROR(#REF!,0) -> 0 | S27: 0 | T27: =R27/($G$18-($G$17-$M$36+$M$37)-$G$15) -> 0 | U27: =IFERROR(VLOOKUP(F27,$D$2:$R$18,8,FALSE),0) -> 0 | V27: =(R27/($G$18-$G$17-$G$15)-S27) -> 0
D29: Sector | E29: Mkt Cap | F29: Equities to Be Sold | G29: Estimate | H29: Shares | J29: % of current position | K29: Share Price | M29: Transaction Amount | Q29: Current Position | R29: Ending Postion | S29: Passive Weight | T29: New Class Weight | U29: Old Active Weight | V29: New Active Weight
D30: IME | E30: =IFERROR(__xludf.DUMMYFUNCTION("iferror(IF(GOOGLEFINANCE(F30,""marketcap"")/1000000>10000,""Large Cap"",IF(GOOGLEFINANCE(F30,""marketcap"")/1000000>2000,""Mid Cap"",""Small Cap"")),"""")"),"Mid Cap") -> Mid Cap | F30: BLBD | G30: =H30*K30 -> 7881 | H30: 100 | I30: <- takes down to 8% 150 takes it to 7.24% | K30: =IFERROR(__xludf.DUMMYFUNCTION("IFERROR(GOOGLEFINANCE(F30,""price""), 0)"),78.81) -> 78.81 | M30: =K30*H30 -> 7881 | Q30: =IFERROR(VLOOKUP(F30,$D$2:$R$17,4,FALSE), 0) -> 24903.96 | R30: =Q30-M30 -> 17022.96 | S30: 0 | T30: =R30/($G$18-($G$17-$M$36+$M$37)-$G$15) -> 0.11326265 | U30: =IFERROR(VLOOKUP(F30,$D$2:$R$18,8,FALSE),0) -> 0.15752838 | V30: =(R30/($G$18-$G$17-$G$15)-S30) -> 0.10767762
D31: Financial | E31: =IFERROR(__xludf.DUMMYFUNCTION("iferror(IF(GOOGLEFINANCE(F31,""marketcap"")/1000000>10000,""Large Cap"",IF(GOOGLEFINANCE(F31,""marketcap"")/1000000>2000,""Mid Cap"",""Small Cap"")),"""")"),"") | F31: HTLF | G31: =H31*K31 -> 0 | H31: 100 | I31: <- takes to 5.89% | K31: =IFERROR(__xludf.DUMMYFUNCTION("IFERROR(GOOGLEFINANCE(F31,""price""), 0)"),0) -> 0 | M31: =K31*H31 -> 0 | Q31: =IFERROR(VLOOKUP(F31,$D$2:$R$37,4,FALSE), 0) -> 0 | R31: =Q31-M31 -> 0 | S31: 0 | T31: =R31/($G$18-($G$17-$M$36+$M$37)-$G$15) -> 0 | U31: =IFERROR(VLOOKUP(F31,$D$2:$R$18,8,FALSE),0) -> 0 | V31: =(R31/($G$18-$G$17-$G$15)-S31) -> 0
E32: =IFERROR(__xludf.DUMMYFUNCTION("iferror(IF(GOOGLEFINANCE(F32,""marketcap"")/1000000>10000,""Large Cap"",IF(GOOGLEFINANCE(F32,""marketcap"")/1000000>2000,""Mid Cap"",""Small Cap"")),"""")"),"") | G32: =H32*K32 -> 0 | H32: =IFERROR(ROUND(VLOOKUP(F32,$D$1:$R$18,2,FALSE)*J32,0),0) -> 0 | K32: =IFERROR(__xludf.DUMMYFUNCTION("IFERROR(GOOGLEFINANCE(F32,""price""), 0)"),0) -> 0 | M32: =K32*H32 -> 0 | Q32: =IFERROR(VLOOKUP(F32,$D$2:$R$37,4,FALSE), 0) -> 0 | R32: =Q32-M32 -> 0 | S32: 0 | T32: =R32/($G$18-($G$17-$M$36+$M$37)-$G$15) -> 0 | U32: =IFERROR(VLOOKUP(F32,$D$2:$R$18,8,FALSE),0) -> 0 | V32: =(R32/($G$18-$G$17-$G$15)-S32) -> 0
E33: =IFERROR(__xludf.DUMMYFUNCTION("iferror(IF(GOOGLEFINANCE(F33,""marketcap"")/1000000>10000,""Large Cap"",IF(GOOGLEFINANCE(F33,""marketcap"")/1000000>2000,""Mid Cap"",""Small Cap"")),"""")"),"") | G33: =H33*K33 -> 0 | H33: =IFERROR(ROUND(VLOOKUP(F33,$D$1:$R$18,2,FALSE)*J33,0),0) -> 0 | K33: =IFERROR(__xludf.DUMMYFUNCTION("IFERROR(GOOGLEFINANCE(F33,""price""), 0)"),0) -> 0 | M33: =K33*H33 -> 0 | Q33: =IFERROR(VLOOKUP(F33,$D$2:$R$37,4,FALSE), 0) -> 0 | R33: =Q33-M33 -> 0 | S33: 0 | T33: =R33/($G$18-($G$17-$M$36+$M$37)-$G$15) -> 0 | U33: =IFERROR(VLOOKUP(F33,$D$2:$R$18,8,FALSE),0) -> 0 | V33: =(R33/($G$18-$G$17-$G$15)-S33) -> 0
M34: =SUM(M24:M27)-SUM(M30:M33) -> -7881
Q35: Current ETF Position | R35: New ETF Position
E36: ETF to Be Sold | F36: IWM | G36: =IF(M34>0, M34, 0) -> 0 | H36: =ROUNDUP(G36/K36,0) -> 0 | J36: =(H36*K36)/G18 -> 0 | K36: =IFERROR(__xludf.DUMMYFUNCTION("GOOGLEFINANCE(F36,""price"")"),299.83) -> 299.83 | M36: =H36*K36 -> 0 | Q36: =$G$15 -> 284586.64 | R36: =Q36-M36 -> 284586.64
E37: ETF to Be Bought | F37: IWM | G37: =IF(M34<0, M34*-1, 0) -> 7881 | H37: =ROUNDDOWN(G37/K37,0) -> 26 | J37: =(H37*K37)/G18 -> 0.017600896 | K37: =IFERROR(__xludf.DUMMYFUNCTION("GOOGLEFINANCE(F37,""price"")"),299.83) -> 299.83 | M37: =H37*K37 -> 7795.58 | Q37: =$G$15 -> 284586.64 | R37: =Q37+M37 -> 292382.22 | S37: =Q37/G18 -> 0.64254101 | T37: =R37/G18 -> 0.6601419
K38: Excess Cash From Transaction | M38: =M36-M37-M34 -> 85.42 | Q38: =G17 -> 229.6 | R38: =Q38+M38 -> 315.02
D39: Sector Allocations
D40: Total Portfolio | G40: Post-Allocation
D41: Sector | E41: Current Mkt. Value | F41: Current Allocation | G41: New Mkt. Value | H41: New Allocation
D42: Consumer | E42: =SUMIF($A$2:$A$18,D42,$G$2:$G$18) -> 0 | F42: =E42/$E$49 -> 0 | G42: =E42+(IF($D$24=D42, $M$24, 0)+IF($D$25=D42, $M$25, 0)+IF($D$26=D42, $M$26, 0)+IF($D$27=D42, $M$27, 0)-IF($D$30=D42, $M$30, 0)-IF($D$31=D42, $M$31, 0)-IF($D$32=D42, $M$32, 0)-IF($D$33=D42,$M$33,0)) -> 0 | H42: =G42/$G$49 -> 0
D43: IME | E43: =SUMIF($A$2:$A$18,D43,$G$2:$G$18) -> 68099.342 | F43: =E43/$E$49 -> 0.153755 | G43: =E43+(IF($D$24=D43, $M$24, 0)+IF($D$25=D43, $M$25, 0)+IF($D$26=D43, $M$26, 0)+IF($D$27=D43, $M$27, 0)-IF($D$30=D43, $M$30, 0)-IF($D$31=D43, $M$31, 0)-IF($D$32=D43, $M$32, 0)-IF($D$33=D43,$M$33,0)) -> 60218.342 | H43: =G43/$G$49 -> 0.13596124
...

Sheet All Positions
A1: Sector | B1: Name | C1: Ticker | D1: Shares | E1: Price | F1: Market Value | G1: Weight
A2: TMT | B2: =IFERROR(__xludf.DUMMYFUNCTION("GOOGLEFINANCE(C2,""Name"")"),"Alphabet Inc Class A") -> Alphabet Inc Class A | C2: GOOGL | D2: =SUMIF('Tall Firs'!$D$8:$D$36,C2,'Tall Firs'!$E$8:$E$36)+SUMIF('Alumni Fund'!$D$2:$D$17,C2,'Alumni Fund'!$E$2:$E$17) -> 586.2232 | E2: =IFERROR(__xludf.DUMMYFUNCTION("GOOGLEFINANCE(C2,""price"")"),337.39) -> 337.39 | F2: =E2*D2 -> 197785.85 | G2: =F2/$F$44 -> #VALUE!
A3: TMT | B3: =IFERROR(__xludf.DUMMYFUNCTION("GOOGLEFINANCE(C3,""Name"")"),"Cisco Systems Inc") -> Cisco Systems Inc | C3: CSCO | D3: =SUMIF('Tall Firs'!$D$8:$D$36,C3,'Tall Firs'!$E$8:$E$36)+SUMIF('Alumni Fund'!$D$2:$D$17,C3,'Alumni Fund'!$E$2:$E$17) -> 670.4639 | E3: =IFERROR(__xludf.DUMMYFUNCTION("GOOGLEFINANCE(C3,""price"")"),113.77) -> 113.77 | F3: =E3*D3 -> 76278.678 | G3: =F3/$F$44 -> #VALUE!
A4: Financial | B4: =IFERROR(__xludf.DUMMYFUNCTION("GOOGLEFINANCE(C4,""Name"")"),"Citigroup Inc") -> Citigroup Inc | C4: C | D4: =SUMIF('Tall Firs'!$D$8:$D$36,C4,'Tall Firs'!$E$8:$E$36)+SUMIF('Alumni Fund'!$D$2:$D$17,C4,'Alumni Fund'!$E$2:$E$17) -> 1001.5849 | E4: =IFERROR(__xludf.DUMMYFUNCTION("GOOGLEFINANCE(C4,""price"")"),141.76) -> 141.76 | F4: =E4*D4 -> 141984.68 | G4: =F4/$F$44 -> #VALUE!
A5: Consumer | B5: =IFERROR(__xludf.DUMMYFUNCTION("GOOGLEFINANCE(C5,""Name"")"),"Amazon.com Inc") -> Amazon.com Inc | C5: AMZN | D5: =SUMIF('Tall Firs'!$D$8:$D$36,C5,'Tall Firs'!$E$8:$E$36)+SUMIF('Alumni Fund'!$D$2:$D$17,C5,'Alumni Fund'!$E$2:$E$17) -> 0 | E5: =IFERROR(__xludf.DUMMYFUNCTION("GOOGLEFINANCE(C5,""price"")"),232.69) -> 232.69 | F5: =E5*D5 -> 0 | G5: =F5/$F$44 -> #VALUE!
A6: TMT | B6: =IFERROR(__xludf.DUMMYFUNCTION("GOOGLEFINANCE(C6,""Name"")"),"Apple Inc") -> Apple Inc | C6: AAPL | D6: =SUMIF('Tall Firs'!$D$8:$D$36,C6,'Tall Firs'!$E$8:$E$36)+SUMIF('Alumni Fund'!$D$2:$D$17,C6,'Alumni Fund'!$E$2:$E$17) -> 0 | E6: =IFERROR(__xludf.DUMMYFUNCTION("GOOGLEFINANCE(C6,""price"")"),283.78) -> 283.78 | F6: =E6*D6 -> 0 | G6: =F6/$F$44 -> #VALUE!
A7: Healthcare | B7: =IFERROR(__xludf.DUMMYFUNCTION("GOOGLEFINANCE(C7,""Name"")"),"Universal Health Services Inc") -> Universal Health Services Inc | C7: UHS | D7: =SUMIF('Tall Firs'!$D$8:$D$36,C7,'Tall Firs'!$E$8:$E$36)+SUMIF('Alumni Fund'!$D$2:$D$17,C7,'Alumni Fund'!$E$2:$E$17) -> 281.5038 | E7: =IFERROR(__xludf.DUMMYFUNCTION("GOOGLEFINANCE(C7,""price"")"),145.69) -> 145.69 | F7: =E7*D7 -> 41012.289 | G7: =F7/$F$44 -> #VALUE!
A8: IME | B8: =IFERROR(__xludf.DUMMYFUNCTION("GOOGLEFINANCE(C8,""Name"")"),"Rtx Corp") -> Rtx Corp | C8: RTX | D8: =SUMIF('Tall Firs'!$D$8:$D$36,C8,'Tall Firs'!$E$8:$E$36)+SUMIF('Alumni Fund'!$D$2:$D$17,C8,'Alumni Fund'!$E$2:$E$17) -> 0 | E8: =IFERROR(__xludf.DUMMYFUNCTION("GOOGLEFINANCE(C8,""price"")"),187.99) -> 187.99 | F8: =E8*D8 -> 0 | G8: =F8/$F$44 -> #VALUE!
A9: Financial | B9: =IFERROR(__xludf.DUMMYFUNCTION("GOOGLEFINANCE(C9,""Name"")"),"Berkshire Hathaway Inc Class B") -> Berkshire Hathaway Inc Class B | C9: BRK.B | D9: =SUMIF('Tall Firs'!$D$8:$D$36,C9,'Tall Firs'!$E$8:$E$36)+SUMIF('Alumni Fund'!$D$2:$D$17,C9,'Alumni Fund'!$E$2:$E$17) -> 96 | E9: =IFERROR(__xludf.DUMMYFUNCTION("GOOGLEFINANCE(C9,""price"")"),498.66) -> 498.66 | F9: =E9*D9 -> 47871.36 | G9: =F9/$F$44 -> #VALUE!
A10: TMT | B10: =IFERROR(__xludf.DUMMYFUNCTION("GOOGLEFINANCE(C10,""Name"")"),"Micron Technology Inc") -> Micron Technology Inc | C10: MU | D10: =SUMIF('Tall Firs'!$D$8:$D$36,C10,'Tall Firs'!$E$8:$E$36)+SUMIF('Alumni Fund'!$D$2:$D$17,C10,'Alumni Fund'!$E$2:$E$17) -> 0 | E10: =IFERROR(__xludf.DUMMYFUNCTION("GOOGLEFINANCE(C10,""price"")"),1132.33) -> 1132.33 | F10: =E10*D10 -> 0 | G10: =F10/$F$44 -> #VALUE!
A11: Financial | B11: =IFERROR(__xludf.DUMMYFUNCTION("GOOGLEFINANCE(C11,""Name"")"),"Evercore Inc") -> Evercore Inc | C11: EVR | D11: =SUMIF('Tall Firs'!$D$8:$D$36,C11,'Tall Firs'!$E$8:$E$36)+SUMIF('Alumni Fund'!$D$2:$D$17,C11,'Alumni Fund'!$E$2:$E$17) -> 241.6099 | E11: =IFERROR(__xludf.DUMMYFUNCTION("GOOGLEFINANCE(C11,""price"")"),342.02) -> 342.02 | F11: =E11*D11 -> 82635.418 | G11: =F11/$F$44 -> #VALUE!
A12: TMT | B12: =IFERROR(__xludf.DUMMYFUNCTION("GOOGLEFINANCE(C12,""Name"")"),"PayPal Holdings Inc") -> PayPal Holdings Inc | C12: PYPL | D12: =SUMIF('Tall Firs'!$D$8:$D$36,C12,'Tall Firs'!$E$8:$E$36)+SUMIF('Alumni Fund'!$D$2:$D$17,C12,'Alumni Fund'!$E$2:$E$17) -> 0 | E12: =IFERROR(__xludf.DUMMYFUNCTION("GOOGLEFINANCE(C12,""price"")"),44.29) -> 44.29 | F12: =E12*D12 -> 0 | G12: =F12/$F$44 -> #VALUE!
A13: TMT | B13: =IFERROR(__xludf.DUMMYFUNCTION("GOOGLEFINANCE(C13,""Name"")"),"VMware Class A Ord Shs") -> VMware Class A Ord Shs | C13: VMW | D13: =SUMIF('Tall Firs'!$D$8:$D$36,C13,'Tall Firs'!$E$8:$E$36)+SUMIF('Alumni Fund'!$D$2:$D$17,C13,'Alumni Fund'!$E$2:$E$17) -> 0 | E13: =IFERROR(__xludf.DUMMYFUNCTION("GOOGLEFINANCE(C13,""price"")"),0) -> 0 | F13: =E13*D13 -> 0 | G13: =F13/$F$44 -> #VALUE!
A14: TMT | B14: =IFERROR(__xludf.DUMMYFUNCTION("GOOGLEFINANCE(C14,""Name"")"),"Walt Disney Co") -> Walt Disney Co | C14: DIS | D14: =SUMIF('Tall Firs'!$D$8:$D$36,C14,'Tall Firs'!$E$8:$E$36)+SUMIF('Alumni Fund'!$D$2:$D$17,C14,'Alumni Fund'!$E$2:$E$17) -> 0 | E14: =IFERROR(__xludf.DUMMYFUNCTION("GOOGLEFINANCE(C14,""price"")"),98.79) -> 98.79 | F14: =E14*D14 -> 0 | G14: =F14/$F$44 -> #VALUE!
A15: IME | B15: =IFERROR(__xludf.DUMMYFUNCTION("GOOGLEFINANCE(C15,""Name"")"),"MillerKnoll Inc") -> MillerKnoll Inc | C15: MLKN | D15: =SUMIF('Tall Firs'!$D$8:$D$36,C15,'Tall Firs'!$E$8:$E$36)+SUMIF('Alumni Fund'!$D$2:$D$17,C15,'Alumni Fund'!$E$2:$E$17) -> 0 | E15: =IFERROR(__xludf.DUMMYFUNCTION("GOOGLEFINANCE(C15,""price"")"),19.96) -> 19.96 | F15: =E15*D15 -> 0 | G15: =F15/$F$44 -> #VALUE!
A16: Healthcare | B16: =IFERROR(__xludf.DUMMYFUNCTION("GOOGLEFINANCE(C16,""Name"")"),"Pfizer Inc") -> Pfizer Inc | C16: PFE | D16: =SUMIF('Tall Firs'!$D$8:$D$36,C16,'Tall Firs'!$E$8:$E$36)+SUMIF('Alumni Fund'!$D$2:$D$17,C16,'Alumni Fund'!$E$2:$E$17) -> 908.8086 | E16: =IFERROR(__xludf.DUMMYFUNCTION("GOOGLEFINANCE(C16,""price"")"),24.29) -> 24.29 | F16: =E16*D16 -> 22074.961 | G16: =F16/$F$44 -> #VALUE!
A17: Healthcare | B17: =IFERROR(__xludf.DUMMYFUNCTION("GOOGLEFINANCE(C17,""Name"")"),"Walgreen Boots Alliance Ord Shs") -> Walgreen Boots Alliance Ord Shs | C17: WBA | D17: =SUMIF('Tall Firs'!$D$8:$D$36,C17,'Tall Firs'!$E$8:$E$36)+SUMIF('Alumni Fund'!$D$2:$D$17,C17,'Alumni Fund'!$E$2:$E$17) -> 0 | E17: =IFERROR(__xludf.DUMMYFUNCTION("GOOGLEFINANCE(C17,""price"")"),222) -> 222 | F17: =E17*D17 -> 0 | G17: =F17/$F$44 -> #VALUE!
A18: TMT | B18: =IFERROR(__xludf.DUMMYFUNCTION("GOOGLEFINANCE(C18,""Name"")"),"Visa Inc") -> Visa Inc | C18: V | D18: =SUMIF('Tall Firs'!$D$8:$D$36,C18,'Tall Firs'!$E$8:$E$36)+SUMIF('Alumni Fund'!$D$2:$D$17,C18,'Alumni Fund'!$E$2:$E$17) -> 0 | E18: =IFERROR(__xludf.DUMMYFUNCTION("GOOGLEFINANCE(C18,""price"")"),336.23) -> 336.23 | F18: =E18*D18 -> 0 | G18: =F18/$F$44 -> #VALUE!
A19: Financial | B19: =IFERROR(__xludf.DUMMYFUNCTION("GOOGLEFINANCE(C19,""Name"")"),"#N/A") -> #N/A | C19: AVTA | D19: =SUMIF('Tall Firs'!$D$8:$D$36,C19,'Tall Firs'!$E$8:$E$36)+SUMIF('Alumni Fund'!$D$2:$D$17,C19,'Alumni Fund'!$E$2:$E$17) -> 0 | E19: =IFERROR(__xludf.DUMMYFUNCTION("GOOGLEFINANCE(C19,""price"")"),"#N/A") -> #N/A | F19: =E19*D19 -> #VALUE! | G19: =F19/$F$44 -> #VALUE!
A20: Consumer | B20: =IFERROR(__xludf.DUMMYFUNCTION("GOOGLEFINANCE(C20,""Name"")"),"LKQ Corp") -> LKQ Corp | C20: LKQ | D20: =SUMIF('Tall Firs'!$D$8:$D$36,C20,'Tall Firs'!$E$8:$E$36)+SUMIF('Alumni Fund'!$D$2:$D$17,C20,'Alumni Fund'!$E$2:$E$17) -> 0 | E20: =IFERROR(__xludf.DUMMYFUNCTION("GOOGLEFINANCE(C20,""price"")"),27.03) -> 27.03 | F20: =E20*D20 -> 0 | G20: =F20/$F$44 -> #VALUE!
A21: TMT | B21: =IFERROR(__xludf.DUMMYFUNCTION("GOOGLEFINANCE(C21,""Name"")"),"Teradyne Inc") -> Teradyne Inc | C21: TER | D21: =SUMIF('Tall Firs'!$D$8:$D$36,C21,'Tall Firs'!$E$8:$E$36)+SUMIF('Alumni Fund'!$D$2:$D$17,C21,'Alumni Fund'!$E$2:$E$17) -> 0 | E21: =IFERROR(__xludf.DUMMYFUNCTION("GOOGLEFINANCE(C21,""price"")"),436.86) -> 436.86 | F21: =E21*D21 -> 0 | G21: =F21/$F$44 -> #VALUE!
A22: Healthcare | B22: =IFERROR(__xludf.DUMMYFUNCTION("GOOGLEFINANCE(C22,""Name"")"),"Regeneron Pharmaceuticals Inc") -> Regeneron Pharmaceuticals Inc | C22: REGN | D22: =SUMIF('Tall Firs'!$D$8:$D$36,C22,'Tall Firs'!$E$8:$E$36)+SUMIF('Alumni Fund'!$D$2:$D$17,C22,'Alumni Fund'!$E$2:$E$17) -> 25.1458 | E22: =IFERROR(__xludf.DUMMYFUNCTION("GOOGLEFINANCE(C22,""price"")"),632.9) -> 632.9 | F22: =E22*D22 -> 15914.777 | G22: =F22/$F$44 -> #VALUE!
A23: IME | B23: =IFERROR(__xludf.DUMMYFUNCTION("GOOGLEFINANCE(C23,""Name"")"),"WRKR Ltd") -> WRKR Ltd | C23: WRK | D23: =SUMIF('Tall Firs'!$D$8:$D$36,C23,'Tall Firs'!$E$8:$E$36)+SUMIF('Alumni Fund'!$D$2:$D$17,C23,'Alumni Fund'!$E$2:$E$17) -> 0 | E23: =IFERROR(__xludf.DUMMYFUNCTION("GOOGLEFINANCE(C23,""price"")"),0.09) -> 0.09 | F23: =E23*D23 -> 0 | G23: =F23/$F$44 -> #VALUE!
A24: Consumer | B24: =IFERROR(__xludf.DUMMYFUNCTION("GOOGLEFINANCE(C24,""Name"")"),"J.M. Smucker Co") -> J.M. Smucker Co | C24: SJM | D24: =SUMIF('Tall Firs'!$D$8:$D$36,C24,'Tall Firs'!$E$8:$E$36)+SUMIF('Alumni Fund'!$D$2:$D$17,C24,'Alumni Fund'!$E$2:$E$17) -> 306.9374 | E24: =IFERROR(__xludf.DUMMYFUNCTION("GOOGLEFINANCE(C24,""price"")"),115.64) -> 115.64 | F24: =E24*D24 -> 35494.241 | G24: =F24/$F$44 -> #VALUE!
A25: Financial | B25: =IFERROR(__xludf.DUMMYFUNCTION("GOOGLEFINANCE(C25,""Name"")"),"S&P Global Inc") -> S&P Global Inc | C25: SPGI | D25: =SUMIF('Tall Firs'!$D$8:$D$36,C25,'Tall Firs'!$E$8:$E$36)+SUMIF('Alumni Fund'!$D$2:$D$17,C25,'Alumni Fund'!$E$2:$E$17) -> 95.8905 | E25: =IFERROR(__xludf.DUMMYFUNCTION("GOOGLEFINANCE(C25,""price"")"),408.16) -> 408.16 | F25: =E25*D25 -> 39138.666 | G25: =F25/$F$44 -> #VALUE!
A26: IME | B26: =IFERROR(__xludf.DUMMYFUNCTION("GOOGLEFINANCE(C26,""Name"")"),"CACI INTERNATIONAL INC Common Stock") -> CACI INTERNATIONAL INC Common Stock | C26: CACI | D26: =SUMIF('Tall Firs'!$D$8:$D$36,C26,'Tall Firs'!$E$8:$E$36)+SUMIF('Alumni Fund'!$D$2:$D$17,C26,'Alumni Fund'!$E$2:$E$17) -> 124 | E26: =IFERROR(__xludf.DUMMYFUNCTION("GOOGLEFINANCE(C26,""price"")"),453.92) -> 453.92 | F26: =E26*D26 -> 56286.08 | G26: =F26/$F$44 -> #VALUE!
A27: TMT | B27: =IFERROR(__xludf.DUMMYFUNCTION("GOOGLEFINANCE(C27,""Name"")"),"Solaredge Technologies Inc") -> Solaredge Technologies Inc | C27: SEDG | D27: =SUMIF('Tall Firs'!$D$8:$D$36,C27,'Tall Firs'!$E$8:$E$36)+SUMIF('Alumni Fund'!$D$2:$D$17,C27,'Alumni Fund'!$E$2:$E$17) -> 0 | E27: =IFERROR(__xludf.DUMMYFUNCTION("GOOGLEFINANCE(C27,""price"")"),51.75) -> 51.75 | F27: =E27*D27 -> 0 | G27: =F27/$F$44 -> #VALUE!
A28: Healthcare | B28: =IFERROR(__xludf.DUMMYFUNCTION("GOOGLEFINANCE(C28,""Name"")"),"McKesson Corp") -> McKesson Corp | C28: MCK | D28: =SUMIF('Tall Firs'!$D$8:$D$36,C28,'Tall Firs'!$E$8:$E$36)+SUMIF('Alumni Fund'!$D$2:$D$17,C28,'Alumni Fund'!$E$2:$E$17) -> 84.4481 | E28: =IFERROR(__xludf.DUMMYFUNCTION("GOOGLEFINANCE(C28,""price"")"),763.51) -> 763.51 | F28: =E28*D28 -> 64476.969 | G28: =F28/$F$44 -> #VALUE!
A29: IME | B29: =IFERROR(__xludf.DUMMYFUNCTION("GOOGLEFINANCE(C29,""Name"")"),"Jabil Inc") -> Jabil Inc | C29: JBL | D29: =SUMIF('Tall Firs'!$D$8:$D$36,C29,'Tall Firs'!$E$8:$E$36)+SUMIF('Alumni Fund'!$D$2:$D$17,C29,'Alumni Fund'!$E$2:$E$17) -> 0 | E29: =IFERROR(__xludf.DUMMYFUNCTION("GOOGLEFINANCE(C29,""price"")"),358.6) -> 358.6 | F29: =E29*D29 -> 0 | G29: =F29/$F$44 -> #VALUE!
A30: Financial | B30: =IFERROR(__xludf.DUMMYFUNCTION("GOOGLEFINANCE(C30,""Name"")"),"Federal National Mortgage Association") -> Federal National Mortgage Association | C30: FNMA | D30: =SUMIF('Tall Firs'!$D$8:$D$36,C30,'Tall Firs'!$E$8:$E$36)+SUMIF('Alumni Fund'!$D$2:$D$17,C30,'Alumni Fund'!$E$2:$E$17) -> 0 | E30: =IFERROR(__xludf.DUMMYFUNCTION("GOOGLEFINANCE(C30,""price"")"),6.88) -> 6.88 | F30: =E30*D30 -> 0 | G30: =F30/$F$44 -> #VALUE!
A31: Consumer | B31: =IFERROR(__xludf.DUMMYFUNCTION("GOOGLEFINANCE(C31,""Name"")"),"Ford Motor Co") -> Ford Motor Co | C31: F | D31: =SUMIF('Tall Firs'!$D$8:$D$36,C31,'Tall Firs'!$E$8:$E$36)+SUMIF('Alumni Fund'!$D$2:$D$17,C31,'Alumni Fund'!$E$2:$E$17) -> 0 | E31: =IFERROR(__xludf.DUMMYFUNCTION("GOOGLEFINANCE(C31,""price"")"),14.13) -> 14.13 | F31: =E31*D31 -> 0 | G31: =F31/$F$44 -> #VALUE!
A32: IME | B32: =IFERROR(__xludf.DUMMYFUNCTION("GOOGLEFINANCE(C32,""Name"")"),"Blue Bird Corp") -> Blue Bird Corp | C32: BLBD | D32: =SUMIF('Tall Firs'!$D$8:$D$36,C32,'Tall Firs'!$E$8:$E$36)+SUMIF('Alumni Fund'!$D$2:$D$17,C32,'Alumni Fund'!$E$2:$E$17) -> 316 | E32: =IFERROR(__xludf.DUMMYFUNCTION("GOOGLEFINANCE(C32,""price"")"),78.81) -> 78.81 | F32: =E32*D32 -> 24903.96 | G32: =F32/$F$44 -> #VALUE!
A33: IME | B33: =IFERROR(__xludf.DUMMYFUNCTION("GOOGLEFINANCE(C33,""Name"")"),"Argan Inc") -> Argan Inc | C33: AGX | D33: =SUMIF('Tall Firs'!$D$8:$D$36,C33,'Tall Firs'!$E$8:$E$36)+SUMIF('Alumni Fund'!$D$2:$D$17,C33,'Alumni Fund'!$E$2:$E$17) -> 46.7 | E33: =IFERROR(__xludf.DUMMYFUNCTION("GOOGLEFINANCE(C33,""price"")"),765.46) -> 765.46 | F33: =E33*D33 -> 35746.982 | G33: =F33/$F$44 -> #VALUE!
A34: TMT | B34: =IFERROR(__xludf.DUMMYFUNCTION("GOOGLEFINANCE(C34,""Name"")"),"InterDigital Inc") -> InterDigital Inc | C34: IDCC | D34: =SUMIF('Tall Firs'!$D$8:$D$36,C34,'Tall Firs'!$E$8:$E$36)+SUMIF('Alumni Fund'!$D$2:$D$17,C34,'Alumni Fund'!$E$2:$E$17) -> 0 | E34: =IFERROR(__xludf.DUMMYFUNCTION("GOOGLEFINANCE(C34,""price"")"),275.86) -> 275.86 | F34: =E34*D34 -> 0 | G34: =F34/$F$44 -> #VALUE!
A35: Financial | B35: =IFERROR(__xludf.DUMMYFUNCTION("GOOGLEFINANCE(C35,""Name"")"),"UMH Properties Inc") -> UMH Properties Inc | C35: UMH | D35: =SUMIF('Tall Firs'!$D$8:$D$36,C35,'Tall Firs'!$E$8:$E$36)+SUMIF('Alumni Fund'!$D$2:$D$17,C35,'Alumni Fund'!$E$2:$E$17) -> 0 | E35: =IFERROR(__xludf.DUMMYFUNCTION("GOOGLEFINANCE(C35,""price"")"),15.45) -> 15.45 | F35: =E35*D35 -> 0 | G35: =F35/$F$44 -> #VALUE!
A36: IME | B36: =IFERROR(__xludf.DUMMYFUNCTION("GOOGLEFINANCE(C36,""Name"")"),"Corteva Inc") -> Corteva Inc | C36: CTVA | D36: =SUMIF('Tall Firs'!$D$8:$D$36,C36,'Tall Firs'!$E$8:$E$36)+SUMIF('Alumni Fund'!$D$2:$D$17,C36,'Alumni Fund'!$E$2:$E$17) -> 763.0004 | E36: =IFERROR(__xludf.DUMMYFUNCTION("GOOGLEFINANCE(C36,""price"")"),82.62) -> 82.62 | F36: =E36*D36 -> 63039.093 | G36: =F36/$F$44 -> #VALUE!
A37: IME | B37: =IFERROR(__xludf.DUMMYFUNCTION("GOOGLEFINANCE(C37,""Name"")"),"Sturm Ruger & Company Inc") -> Sturm Ruger & Company Inc | C37: RGR | D37: =SUMIF('Tall Firs'!$D$8:$D$36,C37,'Tall Firs'!$E$8:$E$36)+SUMIF('Alumni Fund'!$D$2:$D$17,C37,'Alumni Fund'!$E$2:$E$17) -> 0 | E37: =IFERROR(__xludf.DUMMYFUNCTION("GOOGLEFINANCE(C37,""price"")"),38.33) -> 38.33 | F37: =E37*D37 -> 0 | G37: =F37/$F$44 -> #VALUE!
A38: IME | B38: =IFERROR(__xludf.DUMMYFUNCTION("GOOGLEFINANCE(C38,""Name"")"),"Otis Worldwide Corp") -> Otis Worldwide Corp | C38: OTIS | D38: =SUMIF('Tall Firs'!$D$8:$D$36,C38,'Tall Firs'!$E$8:$E$36)+SUMIF('Alumni Fund'!$D$2:$D$17,C38,'Alumni Fund'!$E$2:$E$17) -> 0 | E38: =IFERROR(__xludf.DUMMYFUNCTION("GOOGLEFINANCE(C38,""price"")"),73.19) -> 73.19 | F38: =E38*D38 -> 0 | G38: =F38/$F$44 -> #VALUE!
A39: Healthcare | B39: =IFERROR(__xludf.DUMMYFUNCTION("GOOGLEFINANCE(C39,""Name"")"),"Viatris Inc") -> Viatris Inc | C39: VTRS | D39: =SUMIF('Tall Firs'!$D$8:$D$36,C39,'Tall Firs'!$E$8:$E$36)+SUMIF('Alumni Fund'!$D$2:$D$17,C39,'Alumni Fund'!$E$2:$E$17) -> 0 | E39: =IFERROR(__xludf.DUMMYFUNCTION("GOOGLEFINANCE(C39,""price"")"),16.33) -> 16.33 | F39: =E39*D39 -> 0 | G39: =F39/$F$44 -> #VALUE!
